<?xml version="1.0" encoding="UTF-8"?>
<testsuite name="FirefoxTest"
           tests="3"
           failures="2"
           errors="0"
           skipped="0"
           time="187.003">
  <properties />
            <testcase name="createNewFundingDBcheck" time="59.180" classname="automationFramework.TestCases.CreateFundingDBTest">
                <failure type="java.lang.AssertionError"
                  message="funding record was not found expected [true] but found [false]"
              >
<![CDATA[java.lang.AssertionError: funding record was not found expected [true] but found [false]
  org.testng.Assert.fail(Assert.java:94)
  org.testng.Assert.failNotEquals(Assert.java:494)
  org.testng.Assert.assertTrue(Assert.java:42)
  automationFramework.TestCases.CreateFundingDBTest.createNewFundingDBcheck(CreateFundingDBTest.java:68)
  sun.reflect.NativeMethodAccessorImpl.invoke0(Native Method)
  sun.reflect.NativeMethodAccessorImpl.invoke(Unknown Source)
  sun.reflect.DelegatingMethodAccessorImpl.invoke(Unknown Source)
  java.lang.reflect.Method.invoke(Unknown Source)
  org.testng.internal.MethodInvocationHelper.invokeMethod(MethodInvocationHelper.java:80)
  org.testng.internal.Invoker.invokeMethod(Invoker.java:714)
  org.testng.internal.Invoker.invokeTestMethod(Invoker.java:901)
  org.testng.internal.Invoker.invokeTestMethods(Invoker.java:1231)
  org.testng.internal.TestMethodWorker.invokeTestMethods(TestMethodWorker.java:127)
  org.testng.internal.TestMethodWorker.run(TestMethodWorker.java:111)
  org.testng.TestRunner.privateRun(TestRunner.java:767)
  org.testng.TestRunner.run(TestRunner.java:617)
  org.testng.SuiteRunner.runTest(SuiteRunner.java:334)
  org.testng.SuiteRunner.runSequentially(SuiteRunner.java:329)
  org.testng.SuiteRunner.privateRun(SuiteRunner.java:291)
  org.testng.SuiteRunner.run(SuiteRunner.java:240)
  org.testng.SuiteRunnerWorker.runSuite(SuiteRunnerWorker.java:52)
  org.testng.SuiteRunnerWorker.run(SuiteRunnerWorker.java:86)
  org.testng.TestNG.runSuitesSequentially(TestNG.java:1198)
  org.testng.TestNG.runSuitesLocally(TestNG.java:1123)
  org.testng.TestNG.run(TestNG.java:1031)
  org.testng.remote.AbstractRemoteTestNG.run(AbstractRemoteTestNG.java:126)
  org.testng.remote.RemoteTestNG.initAndRun(RemoteTestNG.java:137)
  org.testng.remote.RemoteTestNG.main(RemoteTestNG.java:58)
]]>
      </failure>

          </testcase>
            <testcase name="createNewFundingCreditCardDBcheck" time="62.601" classname="automationFramework.TestCases.CreateFundingDBTest">
                <failure type="java.lang.AssertionError"
                  message="CC record was not found expected [true] but found [false]"
              >
<![CDATA[java.lang.AssertionError: CC record was not found expected [true] but found [false]
  org.testng.Assert.fail(Assert.java:94)
  org.testng.Assert.failNotEquals(Assert.java:494)
  org.testng.Assert.assertTrue(Assert.java:42)
  automationFramework.TestCases.CreateFundingDBTest.createNewFundingCreditCardDBcheck(CreateFundingDBTest.java:123)
  sun.reflect.NativeMethodAccessorImpl.invoke0(Native Method)
  sun.reflect.NativeMethodAccessorImpl.invoke(Unknown Source)
  sun.reflect.DelegatingMethodAccessorImpl.invoke(Unknown Source)
  java.lang.reflect.Method.invoke(Unknown Source)
  org.testng.internal.MethodInvocationHelper.invokeMethod(MethodInvocationHelper.java:80)
  org.testng.internal.Invoker.invokeMethod(Invoker.java:714)
  org.testng.internal.Invoker.invokeTestMethod(Invoker.java:901)
  org.testng.internal.Invoker.invokeTestMethods(Invoker.java:1231)
  org.testng.internal.TestMethodWorker.invokeTestMethods(TestMethodWorker.java:127)
  org.testng.internal.TestMethodWorker.run(TestMethodWorker.java:111)
  org.testng.TestRunner.privateRun(TestRunner.java:767)
  org.testng.TestRunner.run(TestRunner.java:617)
  org.testng.SuiteRunner.runTest(SuiteRunner.java:334)
  org.testng.SuiteRunner.runSequentially(SuiteRunner.java:329)
  org.testng.SuiteRunner.privateRun(SuiteRunner.java:291)
  org.testng.SuiteRunner.run(SuiteRunner.java:240)
  org.testng.SuiteRunnerWorker.runSuite(SuiteRunnerWorker.java:52)
  org.testng.SuiteRunnerWorker.run(SuiteRunnerWorker.java:86)
  org.testng.TestNG.runSuitesSequentially(TestNG.java:1198)
  org.testng.TestNG.runSuitesLocally(TestNG.java:1123)
  org.testng.TestNG.run(TestNG.java:1031)
  org.testng.remote.AbstractRemoteTestNG.run(AbstractRemoteTestNG.java:126)
  org.testng.remote.RemoteTestNG.initAndRun(RemoteTestNG.java:137)
  org.testng.remote.RemoteTestNG.main(RemoteTestNG.java:58)
]]>
      </failure>

          </testcase>
  
  
            <testcase name="createNewFundingCancelDBcheck" time="65.222" classname="automationFramework.TestCases.CreateFundingDBTest" />
      
</testsuite>
