<?xml version="1.0" encoding="UTF-8"?>
<testsuite name="ChromeTest"
           tests="11"
           failures="3"
           errors="0"
           skipped="0"
           time="144.090">
  <properties />
            <testcase name="updateContactInvalidPhone" time="14.600" classname="automationFramework.TestCases.UpdateContactTest">
                <failure type="java.lang.AssertionError"
                  message="expected [phone[0].number errors.general.invalid.phone.number] but found []"
              >
<![CDATA[java.lang.AssertionError: expected [phone[0].number errors.general.invalid.phone.number] but found []
  org.testng.Assert.fail(Assert.java:94)
  org.testng.Assert.failNotEquals(Assert.java:494)
  org.testng.Assert.assertEquals(Assert.java:123)
  org.testng.Assert.assertEquals(Assert.java:176)
  org.testng.Assert.assertEquals(Assert.java:186)
  automationFramework.TestCases.UpdateContactTest.updateContactInvalidPhone(UpdateContactTest.java:188)
  sun.reflect.NativeMethodAccessorImpl.invoke0(Native Method)
  sun.reflect.NativeMethodAccessorImpl.invoke(Unknown Source)
  sun.reflect.DelegatingMethodAccessorImpl.invoke(Unknown Source)
  java.lang.reflect.Method.invoke(Unknown Source)
  org.testng.internal.MethodInvocationHelper.invokeMethod(MethodInvocationHelper.java:80)
  org.testng.internal.Invoker.invokeMethod(Invoker.java:714)
  org.testng.internal.Invoker.invokeTestMethod(Invoker.java:901)
  org.testng.internal.Invoker.invokeTestMethods(Invoker.java:1231)
  org.testng.internal.TestMethodWorker.invokeTestMethods(TestMethodWorker.java:127)
  org.testng.internal.TestMethodWorker.run(TestMethodWorker.java:111)
  org.testng.TestRunner.privateRun(TestRunner.java:767)
  org.testng.TestRunner.run(TestRunner.java:617)
  org.testng.SuiteRunner.runTest(SuiteRunner.java:334)
  org.testng.SuiteRunner.runSequentially(SuiteRunner.java:329)
  org.testng.SuiteRunner.privateRun(SuiteRunner.java:291)
  org.testng.SuiteRunner.run(SuiteRunner.java:240)
  org.testng.SuiteRunnerWorker.runSuite(SuiteRunnerWorker.java:52)
  org.testng.SuiteRunnerWorker.run(SuiteRunnerWorker.java:86)
  org.testng.TestNG.runSuitesSequentially(TestNG.java:1198)
  org.testng.TestNG.runSuitesLocally(TestNG.java:1123)
  org.testng.TestNG.run(TestNG.java:1031)
  org.testng.remote.AbstractRemoteTestNG.run(AbstractRemoteTestNG.java:126)
  org.testng.remote.RemoteTestNG.initAndRun(RemoteTestNG.java:137)
  org.testng.remote.RemoteTestNG.main(RemoteTestNG.java:58)
]]>
      </failure>

          </testcase>
            <testcase name="updateContactCancel" time="19.406" classname="automationFramework.TestCases.UpdateContactTest">
                <failure type="java.lang.AssertionError"
                  message="expected [4033311371] but found [4033311371,undefined,undefined]"
              >
<![CDATA[java.lang.AssertionError: expected [4033311371] but found [4033311371,undefined,undefined]
  org.testng.Assert.fail(Assert.java:94)
  org.testng.Assert.failNotEquals(Assert.java:494)
  org.testng.Assert.assertEquals(Assert.java:123)
  org.testng.Assert.assertEquals(Assert.java:176)
  org.testng.Assert.assertEquals(Assert.java:186)
  automationFramework.TestCases.UpdateContactTest.updateContactCancel(UpdateContactTest.java:88)
  sun.reflect.NativeMethodAccessorImpl.invoke0(Native Method)
  sun.reflect.NativeMethodAccessorImpl.invoke(Unknown Source)
  sun.reflect.DelegatingMethodAccessorImpl.invoke(Unknown Source)
  java.lang.reflect.Method.invoke(Unknown Source)
  org.testng.internal.MethodInvocationHelper.invokeMethod(MethodInvocationHelper.java:80)
  org.testng.internal.Invoker.invokeMethod(Invoker.java:714)
  org.testng.internal.Invoker.invokeTestMethod(Invoker.java:901)
  org.testng.internal.Invoker.invokeTestMethods(Invoker.java:1231)
  org.testng.internal.TestMethodWorker.invokeTestMethods(TestMethodWorker.java:127)
  org.testng.internal.TestMethodWorker.run(TestMethodWorker.java:111)
  org.testng.TestRunner.privateRun(TestRunner.java:767)
  org.testng.TestRunner.run(TestRunner.java:617)
  org.testng.SuiteRunner.runTest(SuiteRunner.java:334)
  org.testng.SuiteRunner.runSequentially(SuiteRunner.java:329)
  org.testng.SuiteRunner.privateRun(SuiteRunner.java:291)
  org.testng.SuiteRunner.run(SuiteRunner.java:240)
  org.testng.SuiteRunnerWorker.runSuite(SuiteRunnerWorker.java:52)
  org.testng.SuiteRunnerWorker.run(SuiteRunnerWorker.java:86)
  org.testng.TestNG.runSuitesSequentially(TestNG.java:1198)
  org.testng.TestNG.runSuitesLocally(TestNG.java:1123)
  org.testng.TestNG.run(TestNG.java:1031)
  org.testng.remote.AbstractRemoteTestNG.run(AbstractRemoteTestNG.java:126)
  org.testng.remote.RemoteTestNG.initAndRun(RemoteTestNG.java:137)
  org.testng.remote.RemoteTestNG.main(RemoteTestNG.java:58)
]]>
      </failure>

          </testcase>
            <testcase name="updateContact" time="15.300" classname="automationFramework.TestCases.UpdateContactTest">
                <failure type="java.lang.AssertionError"
                  message="expected [indy] but found [robert]"
              >
<![CDATA[java.lang.AssertionError: expected [indy] but found [robert]
  org.testng.Assert.fail(Assert.java:94)
  org.testng.Assert.failNotEquals(Assert.java:494)
  org.testng.Assert.assertEquals(Assert.java:123)
  org.testng.Assert.assertEquals(Assert.java:176)
  org.testng.Assert.assertEquals(Assert.java:186)
  automationFramework.TestCases.UpdateContactTest.updateContact(UpdateContactTest.java:60)
  sun.reflect.NativeMethodAccessorImpl.invoke0(Native Method)
  sun.reflect.NativeMethodAccessorImpl.invoke(Unknown Source)
  sun.reflect.DelegatingMethodAccessorImpl.invoke(Unknown Source)
  java.lang.reflect.Method.invoke(Unknown Source)
  org.testng.internal.MethodInvocationHelper.invokeMethod(MethodInvocationHelper.java:80)
  org.testng.internal.Invoker.invokeMethod(Invoker.java:714)
  org.testng.internal.Invoker.invokeTestMethod(Invoker.java:901)
  org.testng.internal.Invoker.invokeTestMethods(Invoker.java:1231)
  org.testng.internal.TestMethodWorker.invokeTestMethods(TestMethodWorker.java:127)
  org.testng.internal.TestMethodWorker.run(TestMethodWorker.java:111)
  org.testng.TestRunner.privateRun(TestRunner.java:767)
  org.testng.TestRunner.run(TestRunner.java:617)
  org.testng.SuiteRunner.runTest(SuiteRunner.java:334)
  org.testng.SuiteRunner.runSequentially(SuiteRunner.java:329)
  org.testng.SuiteRunner.privateRun(SuiteRunner.java:291)
  org.testng.SuiteRunner.run(SuiteRunner.java:240)
  org.testng.SuiteRunnerWorker.runSuite(SuiteRunnerWorker.java:52)
  org.testng.SuiteRunnerWorker.run(SuiteRunnerWorker.java:86)
  org.testng.TestNG.runSuitesSequentially(TestNG.java:1198)
  org.testng.TestNG.runSuitesLocally(TestNG.java:1123)
  org.testng.TestNG.run(TestNG.java:1031)
  org.testng.remote.AbstractRemoteTestNG.run(AbstractRemoteTestNG.java:126)
  org.testng.remote.RemoteTestNG.initAndRun(RemoteTestNG.java:137)
  org.testng.remote.RemoteTestNG.main(RemoteTestNG.java:58)
]]>
      </failure>

          </testcase>
  
  
            <testcase name="updateContactInvalidPin" time="10.810" classname="automationFramework.TestCases.UpdateContactTest" />
                <testcase name="updateContactCheckRequiredFields" time="10.102" classname="automationFramework.TestCases.UpdateContactTest" />
                <testcase name="updateContactSecurityAnswermissing" time="9.891" classname="automationFramework.TestCases.UpdateContactTest" />
                <testcase name="updateContactInvalidEmail" time="9.721" classname="automationFramework.TestCases.UpdateContactTest" />
                <testcase name="updateContactOtherPhonesMissing" time="10.202" classname="automationFramework.TestCases.UpdateContactTest" />
                <testcase name="updateContactInvalidUserName" time="9.706" classname="automationFramework.TestCases.UpdateContactTest" />
                <testcase name="updateContactAndAddressCancel" time="15.314" classname="automationFramework.TestCases.UpdateContactTest" />
                <testcase name="updateContactAndAddress" time="19.038" classname="automationFramework.TestCases.UpdateContactTest" />
      
</testsuite>
